Workbook
Name Slicer_Approval_Status: #N/A
Name Slicer_Cost_Center: #N/A
Name Slicer_Site_Name: #N/A
Name Slicer_Vendor_Name: #N/A

Sheet Invoice Master
A1: Invoice No | B1: Vendor Name | C1: Site Name | D1: Invoice Date | E1: Month | F1: PO No | G1: GRN No | H1: Amount (₹) | I1: Invoice Code | J1: Cost Center | K1: Type | L1: Funding Status | M1: Priority | N1: Approval Status | O1: Due Date | P1: Paid Date | Q1: Remarks | R1: TAT (Days) | S1: TAT Met | T1: Match Status | U1: Duplicate Flag
A2: INV-003 | B2: Gupta Electricals | C2: Noida-Plaza | D2: 45295 | E2: Jan | F2: PO-103 | G2: GRN-203 | H2: 32000 | I2: AP-ELEC | J2: CC-003 | K2: Invoice | L2: Funded | M2: Urgent | N2: Approved | O2: 45302 | P2: 45301 | Q2: - | R2: =IF(P2="-","-",P2-D2) -> 6 | S2: =IF(R2="-","-",IF(R2<=7,"Yes","No")) -> Yes | T2: =IF(AND(F2<>"MISSING",G2<>"MISSING"),"Matched","Mismatched") -> Matched | U2: =IF(COUNTIFS($B$2:B2,B2,$F$2:F2,F2,$H$2:H2,H2)>1,"DUPLICATE","OK") -> OK
A3: INV-153 | B3: Gupta Electricals | C3: Noida-Plaza | D3: 45296 | E3: Jan | F3: PO-103 | G3: GRN-203 | H3: 32000 | I3: AP-ELEC | J3: CC-003 | K3: Invoice | L3: Funded | M3: Low | N3: On Hold | O3: 45303 | P3: - | Q3: Duplicate detected | R3: =IF(P3="-","-",P3-D3) -> - | S3: =IF(R3="-","-",IF(R3<=7,"Yes","No")) -> - | T3: =IF(AND(F3<>"MISSING",G3<>"MISSING"),"Matched","Mismatched") -> Matched | U3: =IF(COUNTIFS($B$2:B3,B3,$F$2:F3,F3,$H$2:H3,H3)>1,"DUPLICATE","OK") -> DUPLICATE
A4: INV-008 | B4: Gupta Electricals | C4: Faridabad-Mall | D4: 45300 | E4: Jan | F4: PO-108 | G4: GRN-208 | H4: 67000 | I4: AP-ELEC | J4: CC-003 | K4: Invoice | L4: Funded | M4: Normal | N4: Approved | O4: 45307 | P4: 45307 | Q4: - | R4: =IF(P4="-","-",P4-D4) -> 7 | S4: =IF(R4="-","-",IF(R4<=7,"Yes","No")) -> Yes | T4: =IF(AND(F4<>"MISSING",G4<>"MISSING"),"Matched","Mismatched") -> Matched | U4: =IF(COUNTIFS($B$2:B4,B4,$F$2:F4,F4,$H$2:H4,H4)>1,"DUPLICATE","OK") -> OK
A5: INV-158 | B5: Gupta Electricals | C5: Faridabad-Mall | D5: 45301 | E5: Jan | F5: PO-108 | G5: GRN-208 | H5: 67000 | I5: AP-ELEC | J5: CC-003 | K5: Invoice | L5: Funded | M5: Normal | N5: On Hold | O5: 45308 | P5: - | Q5: Duplicate detected | R5: =IF(P5="-","-",P5-D5) -> - | S5: =IF(R5="-","-",IF(R5<=7,"Yes","No")) -> - | T5: =IF(AND(F5<>"MISSING",G5<>"MISSING"),"Matched","Mismatched") -> Matched | U5: =IF(COUNTIFS($B$2:B5,B5,$F$2:F5,F5,$H$2:H5,H5)>1,"DUPLICATE","OK") -> DUPLICATE
A6: INV-013 | B6: Gupta Electricals | C6: Delhi-HQ | D6: 45305 | E6: Jan | F6: PO-113 | G6: GRN-213 | H6: 41000 | I6: AP-ELEC | J6: CC-003 | K6: Invoice | L6: Funded | M6: Low | N6: Approved | O6: 45312 | P6: 45312 | Q6: - | R6: =IF(P6="-","-",P6-D6) -> 7 | S6: =IF(R6="-","-",IF(R6<=7,"Yes","No")) -> Yes | T6: =IF(AND(F6<>"MISSING",G6<>"MISSING"),"Matched","Mismatched") -> Matched | U6: =IF(COUNTIFS($B$2:B6,B6,$F$2:F6,F6,$H$2:H6,H6)>1,"DUPLICATE","OK") -> OK
A7: INV-018 | B7: Gupta Electricals | C7: Gurgaon-Tech | D7: 45310 | E7: Jan | F7: PO-118 | G7: GRN-218 | H7: 52000 | I7: AP-ELEC | J7: CC-003 | K7: Invoice | L7: Funded | M7: Normal | N7: Approved | O7: 45317 | P7: 45317 | Q7: - | R7: =IF(P7="-","-",P7-D7) -> 7 | S7: =IF(R7="-","-",IF(R7<=7,"Yes","No")) -> Yes | T7: =IF(AND(F7<>"MISSING",G7<>"MISSING"),"Matched","Mismatched") -> Matched | U7: =IF(COUNTIFS($B$2:B7,B7,$F$2:F7,F7,$H$2:H7,H7)>1,"DUPLICATE","OK") -> OK
A8: INV-023 | B8: Gupta Electricals | C8: Noida-Plaza | D8: 45315 | E8: Jan | F8: PO-123 | G8: GRN-223 | H8: 77000 | I8: AP-ELEC | J8: CC-003 | K8: Invoice | L8: Funded | M8: Normal | N8: Pending | O8: 45322 | P8: - | Q8: Awaiting approver | R8: =IF(P8="-","-",P8-D8) -> - | S8: =IF(R8="-","-",IF(R8<=7,"Yes","No")) -> - | T8: =IF(AND(F8<>"MISSING",G8<>"MISSING"),"Matched","Mismatched") -> Matched | U8: =IF(COUNTIFS($B$2:B8,B8,$F$2:F8,F8,$H$2:H8,H8)>1,"DUPLICATE","OK") -> OK
A9: INV-028 | B9: Gupta Electricals | C9: Faridabad-Mall | D9: 45320 | E9: Jan | F9: PO-128 | G9: GRN-228 | H9: 66000 | I9: AP-ELEC | J9: CC-003 | K9: Invoice | L9: Funded | M9: Low | N9: Approved | O9: 45327 | P9: 45327 | Q9: - | R9: =IF(P9="-","-",P9-D9) -> 7 | S9: =IF(R9="-","-",IF(R9<=7,"Yes","No")) -> Yes | T9: =IF(AND(F9<>"MISSING",G9<>"MISSING"),"Matched","Mismatched") -> Matched | U9: =IF(COUNTIFS($B$2:B9,B9,$F$2:F9,F9,$H$2:H9,H9)>1,"DUPLICATE","OK") -> OK
A10: INV-002 | B10: Mehta Contractors | C10: Gurgaon-Tech | D10: 45294 | E10: Jan | F10: PO-102 | G10: GRN-202 | H10: 78000 | I10: AP-CIVIL | J10: CC-002 | K10: Invoice | L10: Funded | M10: Normal | N10: Approved | O10: 45301 | P10: 45301 | Q10: - | R10: =IF(P10="-","-",P10-D10) -> 7 | S10: =IF(R10="-","-",IF(R10<=7,"Yes","No")) -> Yes | T10: =IF(AND(F10<>"MISSING",G10<>"MISSING"),"Matched","Mismatched") -> Matched | U10: =IF(COUNTIFS($B$2:B10,B10,$F$2:F10,F10,$H$2:H10,H10)>1,"DUPLICATE","OK") -> OK
A11: INV-152 | B11: Mehta Contractors | C11: Gurgaon-Tech | D11: 45295 | E11: Jan | F11: PO-102 | G11: GRN-202 | H11: 78000 | I11: AP-CIVIL | J11: CC-002 | K11: Invoice | L11: Funded | M11: Normal | N11: On Hold | O11: 45302 | P11: - | Q11: Duplicate of INV-002 | R11: =IF(P11="-","-",P11-D11) -> - | S11: =IF(R11="-","-",IF(R11<=7,"Yes","No")) -> - | T11: =IF(AND(F11<>"MISSING",G11<>"MISSING"),"Matched","Mismatched") -> Matched | U11: =IF(COUNTIFS($B$2:B11,B11,$F$2:F11,F11,$H$2:H11,H11)>1,"DUPLICATE","OK") -> DUPLICATE
A12: INV-007 | B12: Mehta Contractors | C12: Noida-Plaza | D12: 45299 | E12: Jan | F12: PO-107 | G12: GRN-207 | H12: 145000 | I12: AP-CIVIL | J12: CC-002 | K12: Invoice | L12: Funded | M12: Urgent | N12: Approved | O12: 45306 | P12: 45305 | Q12: - | R12: =IF(P12="-","-",P12-D12) -> 6 | S12: =IF(R12="-","-",IF(R12<=7,"Yes","No")) -> Yes | T12: =IF(AND(F12<>"MISSING",G12<>"MISSING"),"Matched","Mismatched") -> Matched | U12: =IF(COUNTIFS($B$2:B12,B12,$F$2:F12,F12,$H$2:H12,H12)>1,"DUPLICATE","OK") -> OK
A13: INV-157 | B13: Mehta Contractors | C13: Noida-Plaza | D13: 45300 | E13: Jan | F13: PO-107 | G13: GRN-207 | H13: 145000 | I13: AP-CIVIL | J13: CC-002 | K13: Invoice | L13: Funded | M13: Urgent | N13: On Hold | O13: 45307 | P13: - | Q13: Duplicate of INV-007 | R13: =IF(P13="-","-",P13-D13) -> - | S13: =IF(R13="-","-",IF(R13<=7,"Yes","No")) -> - | T13: =IF(AND(F13<>"MISSING",G13<>"MISSING"),"Matched","Mismatched") -> Matched | U13: =IF(COUNTIFS($B$2:B13,B13,$F$2:F13,F13,$H$2:H13,H13)>1,"DUPLICATE","OK") -> DUPLICATE
A14: INV-012 | B14: Mehta Contractors | C14: Faridabad-Mall | D14: 45304 | E14: Jan | F14: PO-112 | G14: GRN-212 | H14: 89000 | I14: AP-CIVIL | J14: CC-002 | K14: Invoice | L14: Funded | M14: Normal | N14: Approved | O14: 45311 | P14: 45311 | Q14: - | R14: =IF(P14="-","-",P14-D14) -> 7 | S14: =IF(R14="-","-",IF(R14<=7,"Yes","No")) -> Yes | T14: =IF(AND(F14<>"MISSING",G14<>"MISSING"),"Matched","Mismatched") -> Matched | U14: =IF(COUNTIFS($B$2:B14,B14,$F$2:F14,F14,$H$2:H14,H14)>1,"DUPLICATE","OK") -> OK
A15: INV-017 | B15: Mehta Contractors | C15: Delhi-HQ | D15: 45309 | E15: Jan | F15: PO-117 | G15: GRN-217 | H15: 165000 | I15: AP-CIVIL | J15: CC-002 | K15: Invoice | L15: Funded | M15: Normal | N15: Approved | O15: 45316 | P15: 45316 | Q15: - | R15: =IF(P15="-","-",P15-D15) -> 7 | S15: =IF(R15="-","-",IF(R15<=7,"Yes","No")) -> Yes | T15: =IF(AND(F15<>"MISSING",G15<>"MISSING"),"Matched","Mismatched") -> Matched | U15: =IF(COUNTIFS($B$2:B15,B15,$F$2:F15,F15,$H$2:H15,H15)>1,"DUPLICATE","OK") -> OK
A16: INV-022 | B16: Mehta Contractors | C16: Gurgaon-Tech | D16: 45314 | E16: Jan | F16: PO-122 | G16: GRN-222 | H16: 43000 | I16: AP-CIVIL | J16: CC-002 | K16: Invoice | L16: Pending Funds | M16: Urgent | N16: On Hold | O16: 45321 | P16: - | Q16: Funds not released | R16: =IF(P16="-","-",P16-D16) -> - | S16: =IF(R16="-","-",IF(R16<=7,"Yes","No")) -> - | T16: =IF(AND(F16<>"MISSING",G16<>"MISSING"),"Matched","Mismatched") -> Matched | U16: =IF(COUNTIFS($B$2:B16,B16,$F$2:F16,F16,$H$2:H16,H16)>1,"DUPLICATE","OK") -> OK
A17: INV-027 | B17: Mehta Contractors | C17: Noida-Plaza | D17: 45319 | E17: Jan | F17: PO-127 | G17: GRN-227 | H17: 91000 | I17: AP-CIVIL | J17: CC-002 | K17: Invoice | L17: Funded | M17: Normal | N17: Approved | O17: 45326 | P17: 45326 | Q17: - | R17: =IF(P17="-","-",P17-D17) -> 7 | S17: =IF(R17="-","-",IF(R17<=7,"Yes","No")) -> Yes | T17: =IF(AND(F17<>"MISSING",G17<>"MISSING"),"Matched","Mismatched") -> Matched | U17: =IF(COUNTIFS($B$2:B17,B17,$F$2:F17,F17,$H$2:H17,H17)>1,"DUPLICATE","OK") -> OK
A18: INV-001 | B18: Sharma Supplies | C18: Delhi-HQ | D18: 45293 | E18: Jan | F18: PO-101 | G18: GRN-201 | H18: 45000 | I18: AP-SUPPLY | J18: CC-001 | K18: Invoice | L18: Funded | M18: Normal | N18: Approved | O18: 45300 | P18: 45299 | Q18: - | R18: =IF(P18="-","-",P18-D18) -> 6 | S18: =IF(R18="-","-",IF(R18<=7,"Yes","No")) -> Yes | T18: =IF(AND(F18<>"MISSING",G18<>"MISSING"),"Matched","Mismatched") -> Matched | U18: =IF(COUNTIFS($B$2:B18,B18,$F$2:F18,F18,$H$2:H18,H18)>1,"DUPLICATE","OK") -> OK
A19: INV-151 | B19: Sharma Supplies | C19: Delhi-HQ | D19: 45294 | E19: Jan | F19: PO-101 | G19: GRN-201 | H19: 45000 | I19: AP-SUPPLY | J19: CC-001 | K19: Invoice | L19: Funded | M19: Normal | N19: On Hold | O19: 45301 | P19: - | Q19: Duplicate of INV-001 | R19: =IF(P19="-","-",P19-D19) -> - | S19: =IF(R19="-","-",IF(R19<=7,"Yes","No")) -> - | T19: =IF(AND(F19<>"MISSING",G19<>"MISSING"),"Matched","Mismatched") -> Matched | U19: =IF(COUNTIFS($B$2:B19,B19,$F$2:F19,F19,$H$2:H19,H19)>1,"DUPLICATE","OK") -> DUPLICATE
A20: INV-006 | B20: Sharma Supplies | C20: Gurgaon-Tech | D20: 45298 | E20: Jan | F20: PO-106 | G20: GRN-206 | H20: 23000 | I20: AP-SUPPLY | J20: CC-001 | K20: Invoice | L20: Funded | M20: Low | N20: Approved | O20: 45305 | P20: 45305 | Q20: - | R20: =IF(P20="-","-",P20-D20) -> 7 | S20: =IF(R20="-","-",IF(R20<=7,"Yes","No")) -> Yes | T20: =IF(AND(F20<>"MISSING",G20<>"MISSING"),"Matched","Mismatched") -> Matched | U20: =IF(COUNTIFS($B$2:B20,B20,$F$2:F20,F20,$H$2:H20,H20)>1,"DUPLICATE","OK") -> OK
A21: INV-156 | B21: Sharma Supplies | C21: Gurgaon-Tech | D21: 45299 | E21: Jan | F21: PO-106 | G21: GRN-206 | H21: 23000 | I21: AP-SUPPLY | J21: CC-001 | K21: Invoice | L21: Funded | M21: Low | N21: On Hold | O21: 45306 | P21: - | Q21: Duplicate detected | R21: =IF(P21="-","-",P21-D21) -> - | S21: =IF(R21="-","-",IF(R21<=7,"Yes","No")) -> - | T21: =IF(AND(F21<>"MISSING",G21<>"MISSING"),"Matched","Mismatched") -> Matched | U21: =IF(COUNTIFS($B$2:B21,B21,$F$2:F21,F21,$H$2:H21,H21)>1,"DUPLICATE","OK") -> DUPLICATE
A22: INV-011 | B22: Sharma Supplies | C22: Noida-Plaza | D22: 45303 | E22: Jan | F22: PO-111 | G22: GRN-211 | H22: 54000 | I22: AP-SUPPLY | J22: CC-001 | K22: Invoice | L22: Funded | M22: Normal | N22: Approved | O22: 45310 | P22: 45310 | Q22: - | R22: =IF(P22="-","-",P22-D22) -> 7 | S22: =IF(R22="-","-",IF(R22<=7,"Yes","No")) -> Yes | T22: =IF(AND(F22<>"MISSING",G22<>"MISSING"),"Matched","Mismatched") -> Matched | U22: =IF(COUNTIFS($B$2:B22,B22,$F$2:F22,F22,$H$2:H22,H22)>1,"DUPLICATE","OK") -> OK
A23: INV-016 | B23: Sharma Supplies | C23: Faridabad-Mall | D23: 45308 | E23: Jan | F23: PO-116 | G23: GRN-216 | H23: 29000 | I23: AP-SUPPLY | J23: CC-001 | K23: Invoice | L23: Funded | M23: Low | N23: Approved | O23: 45315 | P23: 45315 | Q23: - | R23: =IF(P23="-","-",P23-D23) -> 7 | S23: =IF(R23="-","-",IF(R23<=7,"Yes","No")) -> Yes | T23: =IF(AND(F23<>"MISSING",G23<>"MISSING"),"Matched","Mismatched") -> Matched | U23: =IF(COUNTIFS($B$2:B23,B23,$F$2:F23,F23,$H$2:H23,H23)>1,"DUPLICATE","OK") -> OK
A24: INV-021 | B24: Sharma Supplies | C24: Delhi-HQ | D24: 45313 | E24: Jan | F24: PO-121 | G24: GRN-221 | H24: 61000 | I24: AP-SUPPLY | J24: CC-001 | K24: Invoice | L24: Funded | M24: Normal | N24: Pending | O24: 45320 | P24: - | Q24: Awaiting approver | R24: =IF(P24="-","-",P24-D24) -> - | S24: =IF(R24="-","-",IF(R24<=7,"Yes","No")) -> - | T24: =IF(AND(F24<>"MISSING",G24<>"MISSING"),"Matched","Mismatched") -> Matched | U24: =IF(COUNTIFS($B$2:B24,B24,$F$2:F24,F24,$H$2:H24,H24)>1,"DUPLICATE","OK") -> OK
A25: INV-026 | B25: Sharma Supplies | C25: Gurgaon-Tech | D25: 45318 | E25: Jan | F25: PO-126 | G25: GRN-226 | H25: 48000 | I25: AP-SUPPLY | J25: CC-001 | K25: Invoice | L25: Funded | M25: Normal | N25: Approved | O25: 45325 | P25: 45325 | Q25: - | R25: =IF(P25="-","-",P25-D25) -> 7 | S25: =IF(R25="-","-",IF(R25<=7,"Yes","No")) -> Yes | T25: =IF(AND(F25<>"MISSING",G25<>"MISSING"),"Matched","Mismatched") -> Matched | U25: =IF(COUNTIFS($B$2:B25,B25,$F$2:F25,F25,$H$2:H25,H25)>1,"DUPLICATE","OK") -> OK
A26: INV-005 | B26: Singh & Co | C26: Delhi-HQ | D26: 45297 | E26: Jan | F26: PO-105 | G26: GRN-205 | H26: 92000 | I26: AP-UTIL | J26: CC-005 | K26: Invoice | L26: Funded | M26: Normal | N26: Approved | O26: 45304 | P26: 45304 | Q26: - | R26: =IF(P26="-","-",P26-D26) -> 7 | S26: =IF(R26="-","-",IF(R26<=7,"Yes","No")) -> Yes | T26: =IF(AND(F26<>"MISSING",G26<>"MISSING"),"Matched","Mismatched") -> Matched | U26: =IF(COUNTIFS($B$2:B26,B26,$F$2:F26,F26,$H$2:H26,H26)>1,"DUPLICATE","OK") -> OK
A27: INV-155 | B27: Singh & Co | C27: Delhi-HQ | D27: 45298 | E27: Jan | F27: PO-105 | G27: GRN-205 | H27: 92000 | I27: AP-UTIL | J27: CC-005 | K27: Invoice | L27: Funded | M27: Urgent | N27: On Hold | O27: 45305 | P27: - | Q27: Duplicate of INV-005 | R27: =IF(P27="-","-",P27-D27) -> - | S27: =IF(R27="-","-",IF(R27<=7,"Yes","No")) -> - | T27: =IF(AND(F27<>"MISSING",G27<>"MISSING"),"Matched","Mismatched") -> Matched | U27: =IF(COUNTIFS($B$2:B27,B27,$F$2:F27,F27,$H$2:H27,H27)>1,"DUPLICATE","OK") -> DUPLICATE
A28: INV-010 | B28: Singh & Co | C28: Gurgaon-Tech | D28: 45302 | E28: Jan | F28: PO-110 | G28: GRN-210 | H28: 112000 | I28: AP-UTIL | J28: CC-005 | K28: Invoice | L28: Funded | M28: Urgent | N28: Approved | O28: 45309 | P28: 45308 | Q28: - | R28: =IF(P28="-","-",P28-D28) -> 6 | S28: =IF(R28="-","-",IF(R28<=7,"Yes","No")) -> Yes | T28: =IF(AND(F28<>"MISSING",G28<>"MISSING"),"Matched","Mismatched") -> Matched | U28: =IF(COUNTIFS($B$2:B28,B28,$F$2:F28,F28,$H$2:H28,H28)>1,"DUPLICATE","OK") -> OK
A29: INV-160 | B29: Singh & Co | C29: Gurgaon-Tech | D29: 45303 | E29: Jan | F29: PO-110 | G29: GRN-210 | H29: 112000 | I29: AP-UTIL | J29: CC-005 | K29: Invoice | L29: Funded | M29: Urgent | N29: On Hold | O29: 45310 | P29: - | Q29: Duplicate of INV-010 | R29: =IF(P29="-","-",P29-D29) -> - | S29: =IF(R29="-","-",IF(R29<=7,"Yes","No")) -> - | T29: =IF(AND(F29<>"MISSING",G29<>"MISSING"),"Matched","Mismatched") -> Matched | U29: =IF(COUNTIFS($B$2:B29,B29,$F$2:F29,F29,$H$2:H29,H29)>1,"DUPLICATE","OK") -> DUPLICATE
A30: INV-015 | B30: Singh & Co | C30: Noida-Plaza | D30: 45307 | E30: Jan | F30: PO-115 | G30: GRN-215 | H30: 128000 | I30: AP-UTIL | J30: CC-005 | K30: Invoice | L30: Funded | M30: Urgent | N30: Approved | O30: 45314 | P30: 45313 | Q30: - | R30: =IF(P30="-","-",P30-D30) -> 6 | S30: =IF(R30="-","-",IF(R30<=7,"Yes","No")) -> Yes | T30: =IF(AND(F30<>"MISSING",G30<>"MISSING"),"Matched","Mismatched") -> Matched | U30: =IF(COUNTIFS($B$2:B30,B30,$F$2:F30,F30,$H$2:H30,H30)>1,"DUPLICATE","OK") -> OK
A31: INV-020 | B31: Singh & Co | C31: Faridabad-Mall | D31: 45312 | E31: Jan | F31: PO-120 | G31: GRN-220 | H31: 97000 | I31: AP-UTIL | J31: CC-005 | K31: Invoice | L31: Funded | M31: Normal | N31: Approved | O31: 45319 | P31: 45319 | Q31: - | R31: =IF(P31="-","-",P31-D31) -> 7 | S31: =IF(R31="-","-",IF(R31<=7,"Yes","No")) -> Yes | T31: =IF(AND(F31<>"MISSING",G31<>"MISSING"),"Matched","Mismatched") -> Matched | U31: =IF(COUNTIFS($B$2:B31,B31,$F$2:F31,F31,$H$2:H31,H31)>1,"DUPLICATE","OK") -> OK
A32: INV-025 | B32: Singh & Co | C32: Delhi-HQ | D32: 45317 | E32: Jan | F32: PO-125 | G32: GRN-225 | H32: 118000 | I32: AP-UTIL | J32: CC-005 | K32: Invoice | L32: Funded | M32: Urgent | N32: Pending | O32: 45324 | P32: - | Q32: Awaiting approver | R32: =IF(P32="-","-",P32-D32) -> - | S32: =IF(R32="-","-",IF(R32<=7,"Yes","No")) -> - | T32: =IF(AND(F32<>"MISSING",G32<>"MISSING"),"Matched","Mismatched") -> Matched | U32: =IF(COUNTIFS($B$2:B32,B32,$F$2:F32,F32,$H$2:H32,H32)>1,"DUPLICATE","OK") -> OK
A33: INV-030 | B33: Singh & Co | C33: Gurgaon-Tech | D33: 45322 | E33: Jan | F33: PO-130 | G33: GRN-230 | H33: 134000 | I33: AP-UTIL | J33: CC-005 | K33: Invoice | L33: Funded | M33: Urgent | N33: Approved | O33: 45329 | P33: 45328 | Q33: - | R33: =IF(P33="-","-",P33-D33) -> 6 | S33: =IF(R33="-","-",IF(R33<=7,"Yes","No")) -> Yes | T33: =IF(AND(F33<>"MISSING",G33<>"MISSING"),"Matched","Mismatched") -> Matched | U33: =IF(COUNTIFS($B$2:B33,B33,$F$2:F33,F33,$H$2:H33,H33)>1,"DUPLICATE","OK") -> OK
A34: INV-004 | B34: Verma Facilities | C34: Faridabad-Mall | D34: 45296 | E34: Jan | F34: PO-104 | G34: GRN-204 | H34: 56000 | I34: AP-MAINT | J34: CC-004 | K34: Invoice | L34: Funded | M34: Normal | N34: Approved | O34: 45303 | P34: 45303 | Q34: - | R34: =IF(P34="-","-",P34-D34) -> 7 | S34: =IF(R34="-","-",IF(R34<=7,"Yes","No")) -> Yes | T34: =IF(AND(F34<>"MISSING",G34<>"MISSING"),"Matched","Mismatched") -> Matched | U34: =IF(COUNTIFS($B$2:B34,B34,$F$2:F34,F34,$H$2:H34,H34)>1,"DUPLICATE","OK") -> OK
A35: INV-154 | B35: Verma Facilities | C35: Faridabad-Mall | D35: 45297 | E35: Jan | F35: PO-104 | G35: GRN-204 | H35: 56000 | I35: AP-MAINT | J35: CC-004 | K35: Invoice | L35: Funded | M35: Normal | N35: On Hold | O35: 45304 | P35: - | Q35: Duplicate detected | R35: =IF(P35="-","-",P35-D35) -> - | S35: =IF(R35="-","-",IF(R35<=7,"Yes","No")) -> - | T35: =IF(AND(F35<>"MISSING",G35<>"MISSING"),"Matched","Mismatched") -> Matched | U35: =IF(COUNTIFS($B$2:B35,B35,$F$2:F35,F35,$H$2:H35,H35)>1,"DUPLICATE","OK") -> DUPLICATE
A36: INV-009 | B36: Verma Facilities | C36: Delhi-HQ | D36: 45301 | E36: Jan | F36: PO-109 | G36: GRN-209 | H36: 38000 | I36: AP-MAINT | J36: CC-004 | K36: Invoice | L36: Funded | M36: Normal | N36: Approved | O36: 45308 | P36: 45308 | Q36: - | R36: =IF(P36="-","-",P36-D36) -> 7 | S36: =IF(R36="-","-",IF(R36<=7,"Yes","No")) -> Yes | T36: =IF(AND(F36<>"MISSING",G36<>"MISSING"),"Matched","Mismatched") -> Matched | U36: =IF(COUNTIFS($B$2:B36,B36,$F$2:F36,F36,$H$2:H36,H36)>1,"DUPLICATE","OK") -> OK
A37: INV-159 | B37: Verma Facilities | C37: Delhi-HQ | D37: 45302 | E37: Jan | F37: PO-109 | G37: GRN-209 | H37: 38000 | I37: AP-MAINT | J37: CC-004 | K37: Invoice | L37: Funded | M37: Normal | N37: On Hold | O37: 45309 | P37: - | Q37: Duplicate detected | R37: =IF(P37="-","-",P37-D37) -> - | S37: =IF(R37="-","-",IF(R37<=7,"Yes","No")) -> - | T37: =IF(AND(F37<>"MISSING",G37<>"MISSING"),"Matched","Mismatched") -> Matched | U37: =IF(COUNTIFS($B$2:B37,B37,$F$2:F37,F37,$H$2:H37,H37)>1,"DUPLICATE","OK") -> DUPLICATE
A38: INV-014 | B38: Verma Facilities | C38: Gurgaon-Tech | D38: 45306 | E38: Jan | F38: PO-114 | G38: GRN-214 | H38: 73000 | I38: AP-MAINT | J38: CC-004 | K38: Invoice | L38: Funded | M38: Normal | N38: Approved | O38: 45313 | P38: 45313 | Q38: - | R38: =IF(P38="-","-",P38-D38) -> 7 | S38: =IF(R38="-","-",IF(R38<=7,"Yes","No")) -> Yes | T38: =IF(AND(F38<>"MISSING",G38<>"MISSING"),"Matched","Mismatched") -> Matched | U38: =IF(COUNTIFS($B$2:B38,B38,$F$2:F38,F38,$H$2:H38,H38)>1,"DUPLICATE","OK") -> OK
A39: INV-019 | B39: Verma Facilities | C39: Noida-Plaza | D39: 45311 | E39: Jan | F39: PO-119 | G39: GRN-219 | H39: 84000 | I39: AP-MAINT | J39: CC-004 | K39: Invoice | L39: Funded | M39: Urgent | N39: Approved | O39: 45318 | P39: 45317 | Q39: - | R39: =IF(P39="-","-",P39-D39) -> 6 | S39: =IF(R39="-","-",IF(R39<=7,"Yes","No")) -> Yes | T39: =IF(AND(F39<>"MISSING",G39<>"MISSING"),"Matched","Mismatched") -> Matched | U39: =IF(COUNTIFS($B$2:B39,B39,$F$2:F39,F39,$H$2:H39,H39)>1,"DUPLICATE","OK") -> OK
A40: INV-024 | B40: Verma Facilities | C40: Faridabad-Mall | D40: 45316 | E40: Jan | F40: PO-124 | G40: GRN-224 | H40: 35000 | I40: AP-MAINT | J40: CC-004 | K40: Invoice | L40: Pending Funds | M40: Low | N40: On Hold | O40: 45323 | P40: - | Q40: Funds not released | R40: =IF(P40="-","-",P40-D40) -> - | S40: =IF(R40="-","-",IF(R40<=7,"Yes","No")) -> - | T40: =IF(AND(F40<>"MISSING",G40<>"MISSING"),"Matched","Mismatched") -> Matched | U40: =IF(COUNTIFS($B$2:B40,B40,$F$2:F40,F40,$H$2:H40,H40)>1,"DUPLICATE","OK") -> OK
...

Sheet Supplier
A1: Supplier Name | B1: Month | C1: Our Ledger (₹) | D1: Supplier Statement (₹) | E1: Difference (₹) | F1: Status | G1: Issue Type | H1: Follow-up Date | I1: Resolution Status | J1: Remarks
A2: Sharma Supplies | B2: Jan | C2: =SUMIFS('Invoice Master'!$H$2:$H$201,'Invoice Master'!$B$2:$B$201,Supplier!A2,'Invoice Master'!$E$2:$E$201,B2) -> 328000 | D2: =SUMIFS('Invoice Master'!$H$2:$H$201,'Invoice Master'!$B$2:$B$201,Supplier!A2,'Invoice Master'!$E$2:$E$201,Supplier!B2,'Invoice Master'!$U$2:$U$201,"OK") -> 260000 | E2: =C2-D2 -> 68000 | F2: =IF(E2=0,"Matched","Unmatched") -> Unmatched | G2: =IF(E2=0,"-","Difference due to duplicate invoice detected") -> Difference due to duplicate invoice detected | H2: 45337 | I2: Pending
A3: Mehta Contractors | B3: Jan | C3: =SUMIFS('Invoice Master'!$H$2:$H$201,'Invoice Master'!$B$2:$B$201,Supplier!A3,'Invoice Master'!$E$2:$E$201,B3) -> 834000 | D3: =SUMIFS('Invoice Master'!$H$2:$H$201,'Invoice Master'!$B$2:$B$201,Supplier!A3,'Invoice Master'!$E$2:$E$201,Supplier!B3,'Invoice Master'!$U$2:$U$201,"Ok") -> 611000 | E3: =C3-D3 -> 223000 | F3: =IF(E3=0,"Matched","Unmatched") -> Unmatched | G3: =IF(E3=0,"-","Difference due to duplicate invoice detected") -> Difference due to duplicate invoice detected | H3: 45337 | I3: Pending
A4: Gupta Electricals | B4: Jan | C4: =SUMIFS('Invoice Master'!$H$2:$H$201,'Invoice Master'!$B$2:$B$201,Supplier!A4,'Invoice Master'!$E$2:$E$201,B4) -> 434000 | D4: =SUMIFS('Invoice Master'!$H$2:$H$201,'Invoice Master'!$B$2:$B$201,Supplier!A4,'Invoice Master'!$E$2:$E$201,Supplier!B4,'Invoice Master'!$U$2:$U$201,"Ok") -> 335000 | E4: =C4-D4 -> 99000 | F4: =IF(E4=0,"Matched","Unmatched") -> Unmatched | G4: =IF(E4=0,"-","Difference due to duplicate invoice detected") -> Difference due to duplicate invoice detected | H4: 45337 | I4: Pending
A5: Verma Facilities | B5: Jan | C5: =SUMIFS('Invoice Master'!$H$2:$H$201,'Invoice Master'!$B$2:$B$201,Supplier!A5,'Invoice Master'!$E$2:$E$201,B5) -> 433000 | D5: =SUMIFS('Invoice Master'!$H$2:$H$201,'Invoice Master'!$B$2:$B$201,Supplier!A5,'Invoice Master'!$E$2:$E$201,Supplier!B5,'Invoice Master'!$U$2:$U$201,"Ok") -> 339000 | E5: =C5-D5 -> 94000 | F5: =IF(E5=0,"Matched","Unmatched") -> Unmatched | G5: =IF(E5=0,"-","Difference due to duplicate invoice detected") -> Difference due to duplicate invoice detected | H5: 45337 | I5: Pending
A6: Singh & Co | B6: Jan | C6: =SUMIFS('Invoice Master'!$H$2:$H$201,'Invoice Master'!$B$2:$B$201,Supplier!A6,'Invoice Master'!$E$2:$E$201,B6) -> 885000 | D6: =SUMIFS('Invoice Master'!$H$2:$H$201,'Invoice Master'!$B$2:$B$201,Supplier!A6,'Invoice Master'!$E$2:$E$201,Supplier!B6,'Invoice Master'!$U$2:$U$201,"Ok") -> 681000 | E6: =C6-D6 -> 204000 | F6: =IF(E6=0,"Matched","Unmatched") -> Unmatched | G6: =IF(E6=0,"-","Difference due to duplicate invoice detected") -> Difference due to duplicate invoice detected | H6: 45337 | I6: Pending
A7: Sharma Supplies | B7: Feb | C7: =SUMIFS('Invoice Master'!$H$2:$H$201,'Invoice Master'!$B$2:$B$201,Supplier!A7,'Invoice Master'!$E$2:$E$201,B7) -> 264000 | D7: =SUMIFS('Invoice Master'!$H$2:$H$201,'Invoice Master'!$B$2:$B$201,Supplier!A7,'Invoice Master'!$E$2:$E$201,Supplier!B7,'Invoice Master'!$U$2:$U$201,"Ok") -> 264000 | E7: =C7-D7 -> 0 | F7: =IF(E7=0,"Matched","Unmatched") -> Matched | G7: =IF(E7=0,"-","Difference due to duplicate invoice detected") -> - | H7: - | I7: -
A8: Mehta Contractors | B8: Feb | C8: =SUMIFS('Invoice Master'!$H$2:$H$201,'Invoice Master'!$B$2:$B$201,Supplier!A8,'Invoice Master'!$E$2:$E$201,B8) -> 533000 | D8: =SUMIFS('Invoice Master'!$H$2:$H$201,'Invoice Master'!$B$2:$B$201,Supplier!A8,'Invoice Master'!$E$2:$E$201,Supplier!B8,'Invoice Master'!$U$2:$U$201,"Ok") -> 533000 | E8: =C8-D8 -> 0 | F8: =IF(E8=0,"Matched","Unmatched") -> Matched | G8: =IF(E8=0,"-","Difference due to duplicate invoice detected") -> - | H8: - | I8: -
A9: Gupta Electricals | B9: Feb | C9: =SUMIFS('Invoice Master'!$H$2:$H$201,'Invoice Master'!$B$2:$B$201,Supplier!A9,'Invoice Master'!$E$2:$E$201,B9) -> 357000 | D9: =SUMIFS('Invoice Master'!$H$2:$H$201,'Invoice Master'!$B$2:$B$201,Supplier!A9,'Invoice Master'!$E$2:$E$201,Supplier!B9,'Invoice Master'!$U$2:$U$201,"Ok") -> 357000 | E9: =C9-D9 -> 0 | F9: =IF(E9=0,"Matched","Unmatched") -> Matched | G9: =IF(E9=0,"-","Difference due to duplicate invoice detected") -> - | H9: - | I9: -
A10: Verma Facilities | B10: Feb | C10: =SUMIFS('Invoice Master'!$H$2:$H$201,'Invoice Master'!$B$2:$B$201,Supplier!A10,'Invoice Master'!$E$2:$E$201,B10) -> 470000 | D10: =SUMIFS('Invoice Master'!$H$2:$H$201,'Invoice Master'!$B$2:$B$201,Supplier!A10,'Invoice Master'!$E$2:$E$201,Supplier!B10,'Invoice Master'!$U$2:$U$201,"Ok") -> 470000 | E10: =C10-D10 -> 0 | F10: =IF(E10=0,"Matched","Unmatched") -> Matched | G10: =IF(E10=0,"-","Difference due to duplicate invoice detected") -> - | H10: - | I10: -
A11: Singh & Co | B11: Feb | C11: =SUMIFS('Invoice Master'!$H$2:$H$201,'Invoice Master'!$B$2:$B$201,Supplier!A11,'Invoice Master'!$E$2:$E$201,B11) -> 768000 | D11: =SUMIFS('Invoice Master'!$H$2:$H$201,'Invoice Master'!$B$2:$B$201,Supplier!A11,'Invoice Master'!$E$2:$E$201,Supplier!B11,'Invoice Master'!$U$2:$U$201,"Ok") -> 768000 | E11: =C11-D11 -> 0 | F11: =IF(E11=0,"Matched","Unmatched") -> Matched | G11: =IF(E11=0,"-","Difference due to duplicate invoice detected") -> - | H11: - | I11: -
A12: Sharma Supplies | B12: Mar | C12: =SUMIFS('Invoice Master'!$H$2:$H$201,'Invoice Master'!$B$2:$B$201,Supplier!A12,'Invoice Master'!$E$2:$E$201,B12) -> 268000 | D12: =SUMIFS('Invoice Master'!$H$2:$H$201,'Invoice Master'!$B$2:$B$201,Supplier!A12,'Invoice Master'!$E$2:$E$201,Supplier!B12,'Invoice Master'!$U$2:$U$201,"Ok") -> 268000 | E12: =C12-D12 -> 0 | F12: =IF(E12=0,"Matched","Unmatched") -> Matched | G12: =IF(E12=0,"-","Difference due to duplicate invoice detected") -> - | H12: - | I12: -
A13: Mehta Contractors | B13: Mar | C13: =SUMIFS('Invoice Master'!$H$2:$H$201,'Invoice Master'!$B$2:$B$201,Supplier!A13,'Invoice Master'!$E$2:$E$201,B13) -> 563000 | D13: =SUMIFS('Invoice Master'!$H$2:$H$201,'Invoice Master'!$B$2:$B$201,Supplier!A13,'Invoice Master'!$E$2:$E$201,Supplier!B13,'Invoice Master'!$U$2:$U$201,"Ok") -> 563000 | E13: =C13-D13 -> 0 | F13: =IF(E13=0,"Matched","Unmatched") -> Matched | G13: =IF(E13=0,"-","Difference due to duplicate invoice detected") -> - | H13: - | I13: -
A14: Gupta Electricals | B14: Mar | C14: =SUMIFS('Invoice Master'!$H$2:$H$201,'Invoice Master'!$B$2:$B$201,Supplier!A14,'Invoice Master'!$E$2:$E$201,B14) -> 389000 | D14: =SUMIFS('Invoice Master'!$H$2:$H$201,'Invoice Master'!$B$2:$B$201,Supplier!A14,'Invoice Master'!$E$2:$E$201,Supplier!B14,'Invoice Master'!$U$2:$U$201,"Ok") -> 389000 | E14: =C14-D14 -> 0 | F14: =IF(E14=0,"Matched","Unmatched") -> Matched | G14: =IF(E14=0,"-","Difference due to duplicate invoice detected") -> - | H14: - | I14: -
A15: Verma Facilities | B15: Mar | C15: =SUMIFS('Invoice Master'!$H$2:$H$201,'Invoice Master'!$B$2:$B$201,Supplier!A15,'Invoice Master'!$E$2:$E$201,B15) -> 415000 | D15: =SUMIFS('Invoice Master'!$H$2:$H$201,'Invoice Master'!$B$2:$B$201,Supplier!A15,'Invoice Master'!$E$2:$E$201,Supplier!B15,'Invoice Master'!$U$2:$U$201,"Ok") -> 415000 | E15: =C15-D15 -> 0 | F15: =IF(E15=0,"Matched","Unmatched") -> Matched | G15: =IF(E15=0,"-","Difference due to duplicate invoice detected") -> - | H15: - | I15: -
A16: Singh & Co | B16: Mar | C16: =SUMIFS('Invoice Master'!$H$2:$H$201,'Invoice Master'!$B$2:$B$201,Supplier!A16,'Invoice Master'!$E$2:$E$201,B16) -> 1045000 | D16: =SUMIFS('Invoice Master'!$H$2:$H$201,'Invoice Master'!$B$2:$B$201,Supplier!A16,'Invoice Master'!$E$2:$E$201,Supplier!B16,'Invoice Master'!$U$2:$U$201,"Ok") -> 1045000 | E16: =C16-D16 -> 0 | F16: =IF(E16=0,"Matched","Unmatched") -> Matched | G16: =IF(E16=0,"-","Difference due to duplicate invoice detected") -> - | H16: - | I16: -
A17: Sharma Supplies | B17: Apr | C17: =SUMIFS('Invoice Master'!$H$2:$H$201,'Invoice Master'!$B$2:$B$201,Supplier!A17,'Invoice Master'!$E$2:$E$201,B17) -> 287000 | D17: =SUMIFS('Invoice Master'!$H$2:$H$201,'Invoice Master'!$B$2:$B$201,Supplier!A17,'Invoice Master'!$E$2:$E$201,Supplier!B17,'Invoice Master'!$U$2:$U$201,"Ok") -> 287000 | E17: =C17-D17 -> 0 | F17: =IF(E17=0,"Matched","Unmatched") -> Matched | G17: =IF(E17=0,"-","Difference due to duplicate invoice detected") -> - | H17: - | I17: -
A18: Mehta Contractors | B18: Apr | C18: =SUMIFS('Invoice Master'!$H$2:$H$201,'Invoice Master'!$B$2:$B$201,Supplier!A18,'Invoice Master'!$E$2:$E$201,B18) -> 510000 | D18: =SUMIFS('Invoice Master'!$H$2:$H$201,'Invoice Master'!$B$2:$B$201,Supplier!A18,'Invoice Master'!$E$2:$E$201,Supplier!B18,'Invoice Master'!$U$2:$U$201,"Ok") -> 510000 | E18: =C18-D18 -> 0 | F18: =IF(E18=0,"Matched","Unmatched") -> Matched | G18: =IF(E18=0,"-","Difference due to duplicate invoice detected") -> - | H18: - | I18: -
... A36: Singh & Co | B36: Jul | C36: =SUMIFS('Invoice Master'!$H$2:$H$201,'Invoice Master'!$B$2:$B$201,Supplier!A36,'Invoice Master'!$E$2:$E$201,B36) -> 324000 | D36: =SUMIFS('Invoice Master'!$H$2:$H$201,'Invoice Master'!$B$2:$B$201,Supplier!A36,'Invoice Master'!$E$2:$E$201,Supplier!B36,'Invoice Master'!$U$2:$U$201,"Ok") -> 324000 | E36: =C36-D36 -> 0 | F36: =IF(E36=0,"Matched","Unmatched") -> Matched | G36: =IF(E36=0,"-","Difference due to duplicate invoice detected") -> - | H36: - | I36: -

Sheet MIS Report
A1: Metric | B1: Value | C1: Target | D1: Status
A2: Total Invoices | B2: =COUNTA('Invoice Master'!A2:A201) -> 200 | C2: - | D2: =IF(B2>=200,"✓ On Track","✗ Monitor") -> ✓ On Track
A3: Approved % | B3: =COUNTIF('Invoice Master'!$N$2:$N$201,"Approved")/B2 -> 0.825 | C3: 1 | D3: =IF(B3>=100,"✓ On Track","✗ Action Needed") -> ✗ Action Needed
A4: Pending | B4: =COUNTIF('Invoice Master'!$N$2:$N$201,A4) -> 9 | C4: 0 | D4: =IF(B4=0,"✓ Clear","✗ Action Needed") -> ✗ Action Needed
A5: On Hold | B5: =COUNTIF('Invoice Master'!$N$2:$N$201,A5) -> 26 | C5: 0 | D5: =IF(B5=0,"✓ Clear","✗ Action Needed") -> ✗ Action Needed
A6: Overdues | B6: =COUNTIFS('Invoice Master'!R2:R201,"-",'Invoice Master'!U2:U201,"ok") -> 25 | C6: 0 | D6: =IF(B6=0,"✓ Clear","✗ Action Needed") -> ✗ Action Needed
A7: Mismatches | B7: =COUNTIF('Invoice Master'!$T$2:$T$201,"Mismatched") -> 9 | C7: 0 | D7: =IF(B7=0,"✓ Clear","✗ Investigate") -> ✗ Investigate
A8: Duplicates Detected | B8: =COUNTIF('Invoice Master'!$U$2:$U$201,"DUPLICATE") -> 10 | C8: 0 | D8: =IF(B8=0,"✓ Clear","✗ Block Payment") -> ✗ Block Payment
A9: TAT Met | B9: =COUNTIF('Invoice Master'!$S$2:$S$201,"Yes")/B2 -> 0.785 | C9: 0.95 | D9: =IF(B9=B2,"✓ 100% TAT","✗ Escalate") -> ✗ Escalate
A10: TAT Breached | B10: =COUNTIF('Invoice Master'!$S$2:$S$201,"No") -> 8 | C10: 0 | D10: =IF(B10=0,"✓ Clear","✗ Escalate") -> ✗ Escalate
A11: Avg TAT | B11: =ROUND(AVERAGE('Invoice Master'!R2:R201),1)&" Days" -> 6.9 Days | C11: 7 | D11: =IF(AVERAGE('Invoice Master'!R2:R201)<7,"✓ On Track","✗ Action Needed") -> ✓ On Track
A12: Total Invoice Value (₹) | B12: =SUMIF('Invoice Master'!$N$2:$N$201,"Approved",'Invoice Master'!$H$2:$H$201) -> 13349000 | C12: - | D12: =IF(B12>0,"✓ Tracked","-") -> ✓ Tracked
A13: Credit Notes Processed | B13: =COUNTIF('Invoice Master'!K:K,"Credit Note") -> 9 | C13: - | D13: =IF(B13>0,"✓ Tracked","-") -> ✓ Tracked

Sheet Pivot
A2: Site and Vendor | D2: Month | H2: Status
A4: Duplicate Flag | B4: OK | D4: Month | E4: Amount | F4: Total Invoices | H4: Approval Status | I4: Total Invoices
D5: Jan | E5: 2914000 | F5: 40 | H5: Pending | I5: 9
A6: Site Name | B6: Avg Amount | D6: Feb | E6: 2392000 | F6: 29 | H6: On Hold | I6: 26
A7: Gurgaon-Tech | B7: 70020.833 | D7: Mar | E7: 2680000 | F7: 31 | H7: Approved | I7: 165
A8: Faridabad-Mall | B8: 73723.404 | D8: Apr | E8: 2562000 | F8: 30
A9: Delhi-HQ | B9: 85145.833 | D9: May | E9: 1918000 | F9: 30
A10: Noida-Plaza | B10: 89106.383 | D10: Jun | E10: 2495000 | F10: 30
D11: Jul | E11: 828000 | F11: 10
A13: Duplicate Flag | B13: OK | D13: Duplicate Flag | E13: OK
D14: Paid Date | E14: -
A15: Vendor Name | B15: Amount
A16: Singh & Co | B16: 5395000 | D16: Month | E16: Total Invoices
A17: Mehta Contractors | B17: 3271000 | D17: Jan | E17: 5
A18: Verma Facilities | B18: 2812000 | D18: Feb | E18: 2
A19: Gupta Electricals | B19: 2134000 | D19: Mar | E19: 9
A20: Sharma Supplies | B20: 1489000 | D20: Apr | E20: 2
D21: May | E21: 2
D22: Jun | E22: 3
D23: Jul | E23: 2

Sheet KPI Dashboard
B1: AP KPI DASHBOARD — RICS & ISAE COMPLIANCE
B4: Process Control Point | C4: Standard | D4: Compliance Status | E4: Evidence
B5: All invoices matched to approved PO before processing | C5: RICS | D5: ✓ Compliant | E5: 3-Way Match column in Invoice Master
B6: GRN confirmed before payment release | C6: ISAE 3402 | D6: ✓ Compliant | E6: GRN No. verified in Invoice Master
B7: Duplicate invoice detection process in place | C7: RICS | D7: ✓ Compliant | E7: Duplicate Detector sheet active
B8: Payment approved by designated approver | C8: RICS | D8: ✓ Compliant | E8: Approval Status tracked in Invoice Master
B9: Supplier reconciliation performed monthly | C9: ISAE 3402 | D9: ✓ Compliant | E9: Supplier Recon sheet — monthly cadence
B10: Funding confirmed before payment run | C10: RICS | D10: ✓ Compliant | E10: Funding Status column tracked
B11: TAT monitored and reported to Team Leader | C11: ISAE 3402 | D11: ✓ Compliant | E11: TAT Met column + MIS Report
B12: Exceptions escalated and logged | C12: RICS | D12: ✓ Compliant | E12: Remarks column + On Hold status
B13: KPIs reported weekly | C13: ISAE 3402 | D13: ✓ Compliant | E13: KPI Dashboard updated weekly
B14: Client financial data maintained confidentially | C14: RICS | D14: ✓ Compliant | E14: Access restricted to authorised users
B15: Production log maintained per invoice | C15: ISAE 3402 | D15: ✓ Compliant | E15: Invoice Master serves as production log
B16: Credit notes processed and reconciled | C16: RICS | D16: ✓ Compliant | E16: Credit Note type tracked in Invoice Master
B18: AP KPI DASHBOARD
